Workbook

Sheet All complaints
A1: Company | B1: count | C1: Fintech? | D1: notes
A2: EQUIFAX, INC. | B2: 3003019 | C2: credit bureat | E2: {=XLOOKUP(proper(A2),'Fintech, Regulatory Arbitrage, '!A:A,'Fintech, Regulatory Arbitrage, '!C:C,"")}
A3: TRANSUNION INTERMEDIATE HOLDINGS, INC. | B3: 2936850 | C3: credit bureat | E3: # of labeled fintechs | F3: =COUNTIF(C2:C5000, "fintech") -> 26 | H3: FINTECHS
A4: Experian Information Solutions Inc. | B4: 2701076 | C4: credit bureat | E4: # of labeled top 100 non credit institutions | F4: =COUNTA(C5:C104) -> 97 | H4: =IFERROR(__xludf.DUMMYFUNCTION("QUERY(A1:C5000, ""select * where C='fintech'"")"),"Company") -> Company | I4: =IFERROR(__xludf.DUMMYFUNCTION("""COMPUTED_VALUE"""),"count") -> count | J4: =IFERROR(__xludf.DUMMYFUNCTION("""COMPUTED_VALUE"""),"Fintech?") -> Fintech?
A5: BANK OF AMERICA, NATIONAL ASSOCIATION | B5: 164949 | C5: non fintech | E5: of those top 100 fintechs = | F5: =COUNTIF(C2:C104, "fintech") -> 15 | H5: =IFERROR(__xludf.DUMMYFUNCTION("""COMPUTED_VALUE"""),"Block, Inc.") -> Block, Inc. | I5: =IFERROR(__xludf.DUMMYFUNCTION("""COMPUTED_VALUE"""),56911.0) -> 56911 | J5: =IFERROR(__xludf.DUMMYFUNCTION("""COMPUTED_VALUE"""),"fintech") -> fintech
A6: WELLS FARGO & COMPANY | B6: 154139 | C6: non fintech | E6: {=XLOOKUP(proper(A6),'Fintech, Regulatory Arbitrage, '!A:A,'Fintech, Regulatory Arbitrage, '!C:C,"")} | H6: =IFERROR(__xludf.DUMMYFUNCTION("""COMPUTED_VALUE"""),"AMERICAN EXPRESS COMPANY") -> AMERICAN EXPRESS COMPANY | I6: =IFERROR(__xludf.DUMMYFUNCTION("""COMPUTED_VALUE"""),49306.0) -> 49306 | J6: =IFERROR(__xludf.DUMMYFUNCTION("""COMPUTED_VALUE"""),"fintech") -> fintech
A7: JPMORGAN CHASE & CO. | B7: 151781 | C7: non fintech | E7: {=XLOOKUP(proper(A7),'Fintech, Regulatory Arbitrage, '!A:A,'Fintech, Regulatory Arbitrage, '!C:C,"")} | H7: =IFERROR(__xludf.DUMMYFUNCTION("""COMPUTED_VALUE"""),"LEXISNEXIS") -> LEXISNEXIS | I7: =IFERROR(__xludf.DUMMYFUNCTION("""COMPUTED_VALUE"""),36136.0) -> 36136 | J7: =IFERROR(__xludf.DUMMYFUNCTION("""COMPUTED_VALUE"""),"fintech") -> fintech
A8: CAPITAL ONE FINANCIAL CORPORATION | B8: 141412 | C8: non fintech | E8: {=XLOOKUP(proper(A8),'Fintech, Regulatory Arbitrage, '!A:A,'Fintech, Regulatory Arbitrage, '!C:C,"")} | H8: =IFERROR(__xludf.DUMMYFUNCTION("""COMPUTED_VALUE"""),"Early Warning Services, LLC") -> Early Warning Services, LLC | I8: =IFERROR(__xludf.DUMMYFUNCTION("""COMPUTED_VALUE"""),31405.0) -> 31405 | J8: =IFERROR(__xludf.DUMMYFUNCTION("""COMPUTED_VALUE"""),"fintech") -> fintech
A9: CITIBANK, N.A. | B9: 120034 | C9: non fintech | E9: {=XLOOKUP(proper(A9),'Fintech, Regulatory Arbitrage, '!A:A,'Fintech, Regulatory Arbitrage, '!C:C,"")} | H9: =IFERROR(__xludf.DUMMYFUNCTION("""COMPUTED_VALUE"""),"Paypal Holdings, Inc") -> Paypal Holdings, Inc | I9: =IFERROR(__xludf.DUMMYFUNCTION("""COMPUTED_VALUE"""),31269.0) -> 31269 | J9: =IFERROR(__xludf.DUMMYFUNCTION("""COMPUTED_VALUE"""),"fintech") -> fintech
A10: SYNCHRONY FINANCIAL | B10: 68742 | C10: non fintech | E10: {=XLOOKUP(proper(A10),'Fintech, Regulatory Arbitrage, '!A:A,'Fintech, Regulatory Arbitrage, '!C:C,"")} | H10: =IFERROR(__xludf.DUMMYFUNCTION("""COMPUTED_VALUE"""),"ALLY FINANCIAL INC.") -> ALLY FINANCIAL INC. | I10: =IFERROR(__xludf.DUMMYFUNCTION("""COMPUTED_VALUE"""),24981.0) -> 24981 | J10: =IFERROR(__xludf.DUMMYFUNCTION("""COMPUTED_VALUE"""),"fintech") -> fintech
A11: Block, Inc. | B11: 56911 | C11: fintech | E11: {=XLOOKUP(proper(A11),'Fintech, Regulatory Arbitrage, '!A:A,'Fintech, Regulatory Arbitrage, '!C:C,"")} | H11: =IFERROR(__xludf.DUMMYFUNCTION("""COMPUTED_VALUE"""),"Chime Financial Inc") -> Chime Financial Inc | I11: =IFERROR(__xludf.DUMMYFUNCTION("""COMPUTED_VALUE"""),17252.0) -> 17252 | J11: =IFERROR(__xludf.DUMMYFUNCTION("""COMPUTED_VALUE"""),"fintech") -> fintech
A12: Resurgent Capital Services L.P. | B12: 49533 | C12: non fintech | D12: debt collection | E12: {=XLOOKUP(proper(A12),'Fintech, Regulatory Arbitrage, '!A:A,'Fintech, Regulatory Arbitrage, '!C:C,"")} | H12: =IFERROR(__xludf.DUMMYFUNCTION("""COMPUTED_VALUE"""),"TRANSWORLD SYSTEMS INC") -> TRANSWORLD SYSTEMS INC | I12: =IFERROR(__xludf.DUMMYFUNCTION("""COMPUTED_VALUE"""),17126.0) -> 17126 | J12: =IFERROR(__xludf.DUMMYFUNCTION("""COMPUTED_VALUE"""),"fintech") -> fintech
A13: AMERICAN EXPRESS COMPANY | B13: 49306 | C13: fintech | D13: kinda? - doesn't have physical branches but is 180 years old | E13: {=XLOOKUP(proper(A13),'Fintech, Regulatory Arbitrage, '!A:A,'Fintech, Regulatory Arbitrage, '!C:C,"")} | H13: =IFERROR(__xludf.DUMMYFUNCTION("""COMPUTED_VALUE"""),"Fidelity National Information Services, Inc. (FNIS)") -> Fidelity National Information Services, Inc. (FNIS) | I13: =IFERROR(__xludf.DUMMYFUNCTION("""COMPUTED_VALUE"""),13637.0) -> 13637 | J13: =IFERROR(__xludf.DUMMYFUNCTION("""COMPUTED_VALUE"""),"fintech") -> fintech
A14: Portfolio Recovery Associates, LLC | B14: 45981 | C14: non fintech | D14: debt collection | E14: {=XLOOKUP(proper(A14),'Fintech, Regulatory Arbitrage, '!A:A,'Fintech, Regulatory Arbitrage, '!C:C,"")} | H14: =IFERROR(__xludf.DUMMYFUNCTION("""COMPUTED_VALUE"""),"Affirm Holdings, Inc") -> Affirm Holdings, Inc | I14: =IFERROR(__xludf.DUMMYFUNCTION("""COMPUTED_VALUE"""),9870.0) -> 9870 | J14: =IFERROR(__xludf.DUMMYFUNCTION("""COMPUTED_VALUE"""),"fintech") -> fintech
A15: ENCORE CAPITAL GROUP INC. | B15: 45898 | C15: non fintech | D15: debt buying | E15: {=XLOOKUP(proper(A15),'Fintech, Regulatory Arbitrage, '!A:A,'Fintech, Regulatory Arbitrage, '!C:C,"")} | H15: =IFERROR(__xludf.DUMMYFUNCTION("""COMPUTED_VALUE"""),"Coinbase, Inc.") -> Coinbase, Inc. | I15: =IFERROR(__xludf.DUMMYFUNCTION("""COMPUTED_VALUE"""),8721.0) -> 8721 | J15: =IFERROR(__xludf.DUMMYFUNCTION("""COMPUTED_VALUE"""),"fintech") -> fintech
A16: U.S. BANCORP | B16: 43636 | C16: non fintech | E16: {=XLOOKUP(proper(A16),'Fintech, Regulatory Arbitrage, '!A:A,'Fintech, Regulatory Arbitrage, '!C:C,"")} | H16: =IFERROR(__xludf.DUMMYFUNCTION("""COMPUTED_VALUE"""),"Self Financial Inc.") -> Self Financial Inc. | I16: =IFERROR(__xludf.DUMMYFUNCTION("""COMPUTED_VALUE"""),7986.0) -> 7986 | J16: =IFERROR(__xludf.DUMMYFUNCTION("""COMPUTED_VALUE"""),"fintech") -> fintech
A17: Navient Solutions, LLC. | B17: 43163 | C17: non fintech | D17: student loans | E17: {=XLOOKUP(proper(A17),'Fintech, Regulatory Arbitrage, '!A:A,'Fintech, Regulatory Arbitrage, '!C:C,"")} | H17: =IFERROR(__xludf.DUMMYFUNCTION("""COMPUTED_VALUE"""),"CORELOGIC INC") -> CORELOGIC INC | I17: =IFERROR(__xludf.DUMMYFUNCTION("""COMPUTED_VALUE"""),7573.0) -> 7573 | J17: =IFERROR(__xludf.DUMMYFUNCTION("""COMPUTED_VALUE"""),"fintech") -> fintech
A18: DISCOVER BANK | B18: 41287 | C18: non fintech | E18: {=XLOOKUP(proper(A18),'Fintech, Regulatory Arbitrage, '!A:A,'Fintech, Regulatory Arbitrage, '!C:C,"")} | H18: =IFERROR(__xludf.DUMMYFUNCTION("""COMPUTED_VALUE"""),"Rocket Mortgage, LLC") -> Rocket Mortgage, LLC | I18: =IFERROR(__xludf.DUMMYFUNCTION("""COMPUTED_VALUE"""),5698.0) -> 5698 | J18: =IFERROR(__xludf.DUMMYFUNCTION("""COMPUTED_VALUE"""),"fintech") -> fintech
A19: NAVY FEDERAL CREDIT UNION | B19: 39929 | C19: non fintech | E19: {=XLOOKUP(proper(A19),'Fintech, Regulatory Arbitrage, '!A:A,'Fintech, Regulatory Arbitrage, '!C:C,"")} | H19: =IFERROR(__xludf.DUMMYFUNCTION("""COMPUTED_VALUE"""),"Netspend Corporation") -> Netspend Corporation | I19: =IFERROR(__xludf.DUMMYFUNCTION("""COMPUTED_VALUE"""),5112.0) -> 5112 | J19: =IFERROR(__xludf.DUMMYFUNCTION("""COMPUTED_VALUE"""),"fintech") -> fintech
A20: Bread Financial Holdings, Inc. | B20: 38874 | C20: non fintech | D20: tech-forward traditional financial services | E20: {=XLOOKUP(proper(A20),'Fintech, Regulatory Arbitrage, '!A:A,'Fintech, Regulatory Arbitrage, '!C:C,"")} | H20: =IFERROR(__xludf.DUMMYFUNCTION("""COMPUTED_VALUE"""),"Credit Karma, LLC") -> Credit Karma, LLC | I20: =IFERROR(__xludf.DUMMYFUNCTION("""COMPUTED_VALUE"""),4238.0) -> 4238 | J20: =IFERROR(__xludf.DUMMYFUNCTION("""COMPUTED_VALUE"""),"fintech") -> fintech
A21: Ocwen Financial Corporation | B21: 36489 | C21: non fintech | D21: mortgage | E21: {=XLOOKUP(proper(A21),'Fintech, Regulatory Arbitrage, '!A:A,'Fintech, Regulatory Arbitrage, '!C:C,"")} | H21: =IFERROR(__xludf.DUMMYFUNCTION("""COMPUTED_VALUE"""),"SOFI TECHNOLOGIES, INC.") -> SOFI TECHNOLOGIES, INC. | I21: =IFERROR(__xludf.DUMMYFUNCTION("""COMPUTED_VALUE"""),3922.0) -> 3922 | J21: =IFERROR(__xludf.DUMMYFUNCTION("""COMPUTED_VALUE"""),"fintech") -> fintech
A22: CBC Companies, Inc. | B22: 36177 | C22: non fintech | E22: {=XLOOKUP(proper(A22),'Fintech, Regulatory Arbitrage, '!A:A,'Fintech, Regulatory Arbitrage, '!C:C,"")} | H22: =IFERROR(__xludf.DUMMYFUNCTION("""COMPUTED_VALUE"""),"FISERV INC.") -> FISERV INC. | I22: =IFERROR(__xludf.DUMMYFUNCTION("""COMPUTED_VALUE"""),2771.0) -> 2771 | J22: =IFERROR(__xludf.DUMMYFUNCTION("""COMPUTED_VALUE"""),"fintech") -> fintech
A23: LEXISNEXIS | B23: 36136 | C23: fintech | D23: I think | E23: {=XLOOKUP(proper(A23),'Fintech, Regulatory Arbitrage, '!A:A,'Fintech, Regulatory Arbitrage, '!C:C,"")} | H23: =IFERROR(__xludf.DUMMYFUNCTION("""COMPUTED_VALUE"""),"AMERISAVE MORTGAGE CORPORATION") -> AMERISAVE MORTGAGE CORPORATION | I23: =IFERROR(__xludf.DUMMYFUNCTION("""COMPUTED_VALUE"""),1619.0) -> 1619 | J23: =IFERROR(__xludf.DUMMYFUNCTION("""COMPUTED_VALUE"""),"fintech") -> fintech
A24: TD BANK US HOLDING COMPANY | B24: 31766 | C24: non fintech | E24: {=XLOOKUP(proper(A24),'Fintech, Regulatory Arbitrage, '!A:A,'Fintech, Regulatory Arbitrage, '!C:C,"")} | H24: =IFERROR(__xludf.DUMMYFUNCTION("""COMPUTED_VALUE"""),"CASHCALL, INC.") -> CASHCALL, INC. | I24: =IFERROR(__xludf.DUMMYFUNCTION("""COMPUTED_VALUE"""),1236.0) -> 1236 | J24: =IFERROR(__xludf.DUMMYFUNCTION("""COMPUTED_VALUE"""),"fintech") -> fintech
A25: Early Warning Services, LLC | B25: 31405 | C25: fintech | D25: I think | E25: {=XLOOKUP(proper(A25),'Fintech, Regulatory Arbitrage, '!A:A,'Fintech, Regulatory Arbitrage, '!C:C,"")} | H25: =IFERROR(__xludf.DUMMYFUNCTION("""COMPUTED_VALUE"""),"GUARANTEED RATE INC.") -> GUARANTEED RATE INC. | I25: =IFERROR(__xludf.DUMMYFUNCTION("""COMPUTED_VALUE"""),718.0) -> 718 | J25: =IFERROR(__xludf.DUMMYFUNCTION("""COMPUTED_VALUE"""),"fintech") -> fintech
A26: Paypal Holdings, Inc | B26: 31269 | C26: fintech | D26: I think | E26: {=XLOOKUP(proper(A26),'Fintech, Regulatory Arbitrage, '!A:A,'Fintech, Regulatory Arbitrage, '!C:C,"")} | H26: =IFERROR(__xludf.DUMMYFUNCTION("""COMPUTED_VALUE"""),"Movement Mortgage LLC") -> Movement Mortgage LLC | I26: =IFERROR(__xludf.DUMMYFUNCTION("""COMPUTED_VALUE"""),458.0) -> 458 | J26: =IFERROR(__xludf.DUMMYFUNCTION("""COMPUTED_VALUE"""),"fintech") -> fintech
A27: PNC Bank N.A. | B27: 28998 | C27: non fintech | E27: {=XLOOKUP(proper(A27),'Fintech, Regulatory Arbitrage, '!A:A,'Fintech, Regulatory Arbitrage, '!C:C,"")} | H27: =IFERROR(__xludf.DUMMYFUNCTION("""COMPUTED_VALUE"""),"Verisk Analytics Inc") -> Verisk Analytics Inc | I27: =IFERROR(__xludf.DUMMYFUNCTION("""COMPUTED_VALUE"""),384.0) -> 384 | J27: =IFERROR(__xludf.DUMMYFUNCTION("""COMPUTED_VALUE"""),"fintech") -> fintech
A28: CL Holdings LLC | B28: 27432 | C28: non fintech | E28: {=XLOOKUP(proper(A28),'Fintech, Regulatory Arbitrage, '!A:A,'Fintech, Regulatory Arbitrage, '!C:C,"")} | H28: =IFERROR(__xludf.DUMMYFUNCTION("""COMPUTED_VALUE"""),"Global Payments Check Services, Inc.") -> Global Payments Check Services, Inc. | I28: =IFERROR(__xludf.DUMMYFUNCTION("""COMPUTED_VALUE"""),81.0) -> 81 | J28: =IFERROR(__xludf.DUMMYFUNCTION("""COMPUTED_VALUE"""),"fintech") -> fintech
A29: ALLY FINANCIAL INC. | B29: 24981 | C29: fintech | E29: {=XLOOKUP(proper(A29),'Fintech, Regulatory Arbitrage, '!A:A,'Fintech, Regulatory Arbitrage, '!C:C,"")} | H29: =IFERROR(__xludf.DUMMYFUNCTION("""COMPUTED_VALUE"""),"ACI Worldwide, Corp.") -> ACI Worldwide, Corp. | I29: =IFERROR(__xludf.DUMMYFUNCTION("""COMPUTED_VALUE"""),43.0) -> 43 | J29: =IFERROR(__xludf.DUMMYFUNCTION("""COMPUTED_VALUE"""),"fintech") -> fintech
A30: BARCLAYS BANK DELAWARE | B30: 23678 | C30: non fintech | E30: {=XLOOKUP(proper(A30),'Fintech, Regulatory Arbitrage, '!A:A,'Fintech, Regulatory Arbitrage, '!C:C,"")} | H30: =IFERROR(__xludf.DUMMYFUNCTION("""COMPUTED_VALUE"""),"Homeward, Inc.") -> Homeward, Inc. | I30: =IFERROR(__xludf.DUMMYFUNCTION("""COMPUTED_VALUE"""),4.0) -> 4 | J30: =IFERROR(__xludf.DUMMYFUNCTION("""COMPUTED_VALUE"""),"fintech") -> fintech
A31: Nelnet, Inc. | B31: 21590 | C31: non fintech | E31: {=XLOOKUP(proper(A31),'Fintech, Regulatory Arbitrage, '!A:A,'Fintech, Regulatory Arbitrage, '!C:C,"")}
A32: MOHELA | B32: 21457 | C32: non fintech | D32: student aid | E32: {=XLOOKUP(proper(A32),'Fintech, Regulatory Arbitrage, '!A:A,'Fintech, Regulatory Arbitrage, '!C:C,"")}
A33: TRUIST FINANCIAL CORPORATION | B33: 19504 | C33: non fintech | E33: {=XLOOKUP(proper(A33),'Fintech, Regulatory Arbitrage, '!A:A,'Fintech, Regulatory Arbitrage, '!C:C,"")}
A34: NATIONSTAR MORTGAGE LLC | B34: 19296 | C34: non fintech | E34: {=XLOOKUP(proper(A34),'Fintech, Regulatory Arbitrage, '!A:A,'Fintech, Regulatory Arbitrage, '!C:C,"")}
A35: CCS Financial Services, Inc. | B35: 18834 | C35: non fintech | E35: {=XLOOKUP(proper(A35),'Fintech, Regulatory Arbitrage, '!A:A,'Fintech, Regulatory Arbitrage, '!C:C,"")}
A36: I.C. System, Inc. | B36: 17739 | C36: non fintech | D36: credit recovery | E36: {=XLOOKUP(proper(A36),'Fintech, Regulatory Arbitrage, '!A:A,'Fintech, Regulatory Arbitrage, '!C:C,"")}
A37: Chime Financial Inc | B37: 17252 | C37: fintech | E37: {=XLOOKUP(proper(A37),'Fintech, Regulatory Arbitrage, '!A:A,'Fintech, Regulatory Arbitrage, '!C:C,"")} | H37: paper | I37: https://www.sciencedirect.com/science/article/pii/S1057521920301885
A38: TRANSWORLD SYSTEMS INC | B38: 17126 | C38: fintech | E38: {=XLOOKUP(proper(A38),'Fintech, Regulatory Arbitrage, '!A:A,'Fintech, Regulatory Arbitrage, '!C:C,"")}
A39: UNITED SERVICES AUTOMOBILE ASSOCIATION | B39: 16739 | C39: non fintech | E39: {=XLOOKUP(proper(A39),'Fintech, Regulatory Arbitrage, '!A:A,'Fintech, Regulatory Arbitrage, '!C:C,"")}
A40: AES/PHEAA | B40: 16267 | C40: non fintech | D40: student loans | E40: {=XLOOKUP(proper(A40),'Fintech, Regulatory Arbitrage, '!A:A,'Fintech, Regulatory Arbitrage, '!C:C,"")}
...

Sheet Original
A1: Company | B1: proportion | C1: GPT classification | D1: AI Adoption (0-no, 1-yes) | E1: Date (MM/YYYY) | F1: Link
A2: BANK OF AMERICA, NATIONAL ASSOCIATION | B2: 1.4025022 | C2: 1 | D2: 1 | E2: 43252 | F2: BofA’s Erica Surpasses 1.5 Billion Client Interactions, Totaling More Than 10 Million Hours of Conversations | Press Releases | Newsroom | Bank of America
A3: WELLS FARGO & COMPANY | B3: 1.3105887 | C3: 1 | D3: 1 | E3: 45352 | F3: Wells Fargo’s assistant, powered by Google's AI, poised to hit 100 million interactions annually | VentureBeat
A4: JPMORGAN CHASE & CO. | B4: 1.2905394 | C4: 1 | D4: 1 | E4: 43800 | F4: JPMorgan’s CIO Has Championed A Data Platform That Turbocharges AI
A5: CAPITAL ONE FINANCIAL CORPORATION | B5: 1.2023755 | C5: 1 | D5: 1 | E5: 42795 | F5: Capital One launches 'Eno' SMS chatbot for managing your credit card & bank accounts - 9to5Mac
A6: CITIBANK, N.A. | B6: 1.0206061 | C6: 1 | D6: 1
A7: SYNCHRONY FINANCIAL | B7: 0.58448858 | C7: 1 | D7: 1 | E7: 43374 | F7: Synchrony Harnesses AI to Transform Customer Experience
A8: Block, Inc. | B8: 0.48389383
A9: Resurgent Capital Services L.P. | B9: 0.42116134
A10: AMERICAN EXPRESS COMPANY | B10: 0.41923124 | C10: 1 | D10: 1
A11: Portfolio Recovery Associates, LLC | B11: 0.39095996
A12: ENCORE CAPITAL GROUP INC. | B12: 0.39025424
A13: U.S. BANCORP | B13: 0.37102126
A14: Navient Solutions, LLC. | B14: 0.36699951
A15: DISCOVER BANK | B15: 0.35104856
A16: NAVY FEDERAL CREDIT UNION | B16: 0.33950197
A17: Bread Financial Holdings, Inc. | B17: 0.33053168
A18: Ocwen Financial Corporation | B18: 0.31025288
A19: CBC Companies, Inc. | B19: 0.30760006
A20: LEXISNEXIS | B20: 0.30725145
A21: TD BANK US HOLDING COMPANY | B21: 0.27009491
A22: Early Warning Services, LLC | B22: 0.26702546
... A25: CL Holdings LLC | B25: 0.23324446
A26: ALLY FINANCIAL INC. | B26: 0.21240449 | C26: 1 | D26: 1 | E26: 45839 | F26: https://media.ally.com/2025-07-23-Ally-Financial-rolls-out-proprietary-AI-platform-enterprise-wide
A27: BARCLAYS BANK DELAWARE | B27: 0.20132554 | C27: 0 | D27: 1 | E27: 45840 | F27: https://home.barclays/insights/2025/07/scaling-AI-at-Barclays/
A28: Nelnet, Inc. | B28: 0.18357203 | C28: 0 | D28: 1 | E28: 45261 | F28: https://nelnetinc.com/blog/unlocking-the-power-of-ai-at-nelnet/
A29: MOHELA | B29: 0.18244118 | C29: 0 | D29: 0
A30: TRUIST FINANCIAL CORPORATION | B30: 0.16583552 | C30: 1 | D30: 1 | E30: 44805 | F30: https://media.truist.com/2022-09-15-Truist-launches-Truist-Assist#:~:text=Truist%20launches%20Truist%20Assist%20%2D%20Sep%2015%2C%202022
A31: NATIONSTAR MORTGAGE LLC | B31: 0.16406697 | C31: 1 | D31: 1 | E31: 45689 | F31: https://nationalmortgageprofessional.com/news/mr-cooper-bets-big-ai-expands-tech-better-cx
A32: CCS Financial Services, Inc. | B32: 0.16013875 | C32: 0 | D32: 0
A33: I.C. System, Inc. | B33: 0.15082836 | C33: 0 | D33: 0
A34: Chime Financial Inc | B34: 0.14668757 | C34: 0 | D34: 1 | E34: 43101 | F34: https://openai.com/index/chime-vineet-mehra/ | G34: https://thefinancialbrand.com/news/artificial-intelligence-banking/predictive-analytics-digital-banking-website-accounts-73355
A35: TRANSWORLD SYSTEMS INC | B35: 0.14561624 | C35: 0 | D35: 1 | E35: 45536 | F35: https://tsico.com/revolutionizing-patient-experience-how-tsi-is-redefining-healthcare-through-outsourcing/
A36: UNITED SERVICES AUTOMOBILE ASSOCIATION | B36: 0.14232572 | C36: 1 | D36: 1 | E36: 45778 | F36: https://www.techtarget.com/searchenterpriseai/news/366623771/USAA-takes-an-experiment-and-see-approach-with-AI#:~:text=Across%20the%20board%2C%20we%20are,need%20to%20answer%20the%20questions.
A37: AES/PHEAA | B37: 0.13831247 | C37: 0 | D37: 0
A38: CITIZENS FINANCIAL GROUP, INC. | B38: 0.13804889 | C38: 0 | D38: 1 | E38: 45536 | F38: https://finainews.com/banking/citizens-sees-up-to-20-efficiency-gains-through-gen-ai/#:~:text=Citizens%20Bank%20has%20deployed%20generative,efficiency%20gains%20are%20adding%20up.
A39: Shellpoint Partners, LLC | B39: 0.13396762 | C39: 0 | D39: 0
A40: SELECT PORTFOLIO SERVICING, INC. | B40: 0.13062608 | C40: 0 | D40: 0
A41: GOLDMAN SACHS BANK USA | B41: 0.12994587 | C41: 1
A42: Ditech Financial LLC | B42: 0.12714 | C42: 0 | D42: 0
...

Sheet Fintech, Regulatory Arbitrage, 
A1: Fintech, Regulatory Arbitrage, and the Rise of Shadow Banks | B1: Greg Buchak* Gregor Matvos Tomasz Piskorski Amit Seru
A2: Name | B2: Bank Type | C2: Fintech or Non-Fintech
A3: Amerisave Mortgage | B3: Shadow Bank | C3: Fintech
A4: Cashcall Inc | B4: Shadow Bank | C4: Fintech
A5: Guaranteed Rate Inc | B5: Shadow Bank | C5: Fintech
A6: Homebridge Financial Services | B6: Shadow Bank | C6: Fintech | D6: not foundin cfpb
A7: Homeward Residential | B7: Shadow Bank | C7: Fintech
A8: Movement Mortgage | B8: Shadow Bank | C8: Fintech
A9: Quicken Loans | B9: Shadow Bank | C9: Fintech | D9: this is called rocket now
A10: Academy Mortgage | B10: Shadow Bank | C10: Non-Fintech
A11: AmCap Mortgage LTD | B11: Shadow Bank | C11: Non-Fintech
A12: American Neighborhood Mtg | B12: Shadow Bank | C12: Non-Fintech
A13: American Pacific Mortgage | B13: Shadow Bank | C13: Non-Fintech
A14: Amerifirst Financial Corp | B14: Shadow Bank | C14: Non-Fintech
A15: Amerihome Mortgage | B15: Shadow Bank | C15: Non-Fintech
A16: Ark-LA-TEX Fin Svcs. | B16: Shadow Bank | C16: Non-Fintech
A17: Bay Equity | B17: Shadow Bank | C17: Non-Fintech
A18: Broker Solutions | B18: Shadow Bank | C18: Non-Fintech
A19: Caliber Home Loans | B19: Shadow Bank | C19: Non-Fintech
A20: Chicago Mortgage Solutions | B20: Shadow Bank | C20: Non-Fintech
A21: CMG Mortgage | B21: Shadow Bank | C21: Non-Fintech
... A49: Walker and Dunlop | B49: Shadow Bank | C49: Non-Fintech
A50: Allay Bank | B50: Traditional Bank
A51: Bank of America | B51: Traditional Bank
A52: BOK Financial | B52: Traditional Bank
A53: Branch Banking and Trust Company | B53: Traditional Bank
A54: Capital One | B54: Traditional Bank
A55: Citibank | B55: Traditional Bank
A56: Citimortgage | B56: Traditional Bank
A57: Colorado FSB | B57: Traditional Bank
A58: Everbank | B58: Traditional Bank
A59: FHLB Chicago | B59: Traditional Bank
A60: Fidelity Bank | B60: Traditional Bank
A61: Fifth Third Mortgage | B61: Traditional Bank
... A81: Wells Fargo Bank | B81: Traditional Bank

Sheet TOP 25 CLOSED-END RESPONDENTS B
A1: Source: | B1: https://files.consumerfinance.gov/f/documents/cfpb_2023-mortgage-market-activity-and-trends_2024-12.pdf
B2: Table 6A
A3: Institution | B3: Institution Type | C3: Total Originations (thousands) | D3: Market Share (%) | E3: Total Purchases (thousands)
A4: Rocket Mortgage, LLC | B4: Independent Mortgage Company | C4: 288 | D4: 6.2 | E4: 4.2
A5: United Wholesale Mortgage, LLC | B5: Independent Mortgage Company | C5: 287 | D5: 6.2 | E5: 1.3
A6: Fairway Independent Mortgage Corporation | B6: Independent Mortgage Company | C6: 85 | D6: 1.8 | E6: <1
A7: Crosscountry Mortgage, LLC | B7: Independent Mortgage Company | C7: 84 | D7: 1.8 | E7: <1
A8: Loandepot.Com, LLC | B8: Independent Mortgage Company | C8: 65 | D8: 1.4 | E8: <1
A9: DHI Mortgage Company, Ltd. | B9: Affiliated Mortgage Company | C9: 65 | D9: 1.4 | E9: <1
A10: JPMorgan Chase Bank, National Association | B10: Large Bank | C10: 63 | D10: 1.4 | E10: 128
A11: Mortgage Research Center, LLC | B11: Independent Mortgage Company | C11: 62 | D11: 1.3 | E11: <1
A12: Movement Mortgage, LLC | B12: Independent Mortgage Company | C12: 59 | D12: 1.3 | E12: <1
A13: Guaranteed Rate, Inc. | B13: Independent Mortgage Company | C13: 56 | D13: 1.2 | E13: 29
A14: Navy Federal Credit Union | B14: Credit Union | C14: 55 | D14: 1.2 | E14: <1
A15: Wells Fargo Bank, National Association | B15: Large Bank | C15: 51 | D15: 1.1 | E15: 6
A16: U.S. Bank National Association | B16: Large Bank | C16: 49 | D16: 1.1 | E16: 58
A17: Guild Mortgage Company LLC | B17: Independent Mortgage Company | C17: 48 | D17: 1 | E17: 2
A18: Lennar Mortgage, LLC | B18: Independent Mortgage Company | C18: 47 | D18: 1 | E18: <1
A19: PennyMac Loan Services, LLC | B19: Independent Mortgage Company | C19: 47 | D19: 1 | E19: 218
A20: CMG Mortgage, Inc. | B20: Independent Mortgage Company | C20: 42 | D20: 0.9 | E20: 12
A21: Newrez LLC | B21: Independent Mortgage Company | C21: 32 | D21: 0.7 | E21: 71
A22: New American Funding, LLC | B22: Independent Mortgage Company | C22: 32 | D22: 0.7 | E22: <1
A23: Discover Bank | B23: Large Bank | C23: 31 | D23: 0.7 | E23: <1
A24: Nationstar Mortgage LLC | B24: Independent Mortgage Company | C24: 28 | D24: 0.6 | E24: 19
A25: Bank of America, National Association | B25: Large Bank | C25: 27.9 | D25: 0.6 | E25: 8.4
A26: 21st Mortgage Corporation | B26: Independent Mortgage Company | C26: 27.8 | D26: 0.6 | E26: 3.4
A27: Cardinal Financial Company, Limited Partnership | B27: Independent Mortgage Company | C27: 27.2 | D27: 0.6 | E27: <1
A28: Primelending, A Plainscapital Company | B28: Affiliated Mortgage Company | C28: 26 | D28: 0.6 | E28: <1
A29: Top 25 Institutions (Total) | B29: – | C29: 1687.3 | D29: – | E29: 561.2
A30: All Institutions (Total) | B30: – | C30: 4627.4 | D30: – | E30: 1212.2
